Workbook

Sheet Plan
A1: Grundriss - Hoehe relativ zur Raummitte [mm], positiv = hoeher
A2: Blick von oben, wie die Skizze. Raster 200 mm. Graue Flaeche = Raum, weiss = ausserhalb (Kerbe oben links).
A3: Hoehe relativ zur Raummitte [mm]
Y5: =Messpunkte!F2 | AI5: =Messpunkte!F3
Y6: =Messpunkte!F4 | AE6: =Messpunkte!F5 | AJ6: =Messpunkte!F6
Y8: =Messpunkte!F7 | AE8: =Messpunkte!F8 | AI8: =Messpunkte!F9
AA9: =Messpunkte!F10
AI10: =Messpunkte!F11
AC12: =Messpunkte!F12
A14: =Messpunkte!F13 | B14: =Messpunkte!F16 | C14: =Messpunkte!F17 | K14: =Messpunkte!F14 | L14: =Messpunkte!F18 | V14: =Messpunkte!F15 | W14: =Messpunkte!F19
C15: =Messpunkte!F20 | K15: =Messpunkte!F21 | V15: =Messpunkte!F22
AL16: =Messpunkte!F27
A17: =Messpunkte!F23
T19: =Messpunkte!F24
J21: =Messpunkte!F25 | AF21: =Messpunkte!F26
AL23: =Messpunkte!F28
T25: =Messpunkte!F35 | AD25: =Messpunkte!F36 | AL25: =Messpunkte!F29
E26: =Messpunkte!F31
A27: =Messpunkte!F32 | AL27: =Messpunkte!F30
Q28: =Messpunkte!F37 | S28: =Messpunkte!F38 | V28: =Messpunkte!F39 | AD28: =Messpunkte!F40
A29: =Messpunkte!F33 | D29: =Messpunkte!F34 | AK29: =Messpunkte!F41
A32: Rohmesswerte [mm] - zum Abgleich mit der Skizze
Y34: =Messpunkte!E2 | AI34: =Messpunkte!E3
Y35: =Messpunkte!E4 | AE35: =Messpunkte!E5 | AJ35: =Messpunkte!E6
Y37: =Messpunkte!E7 | AE37: =Messpunkte!E8 | AI37: =Messpunkte!E9
AA38: =Messpunkte!E10
AI39: =Messpunkte!E11
AC41: =Messpunkte!E12
A43: =Messpunkte!E13 | B43: =Messpunkte!E16 | C43: =Messpunkte!E17 | K43: =Messpunkte!E14 | L43: =Messpunkte!E18 | V43: =Messpunkte!E15 | W43: =Messpunkte!E19
C44: =Messpunkte!E20 | K44: =Messpunkte!E21 | V44: =Messpunkte!E22
AL45: =Messpunkte!E27
A46: =Messpunkte!E23
T48: =Messpunkte!E24
J50: =Messpunkte!E25 | AF50: =Messpunkte!E26
AL52: =Messpunkte!E28
T54: =Messpunkte!E35 | AD54: =Messpunkte!E36 | AL54: =Messpunkte!E29
E55: =Messpunkte!E31
A56: =Messpunkte!E32 | AL56: =Messpunkte!E30
Q57: =Messpunkte!E37 | S57: =Messpunkte!E38 | V57: =Messpunkte!E39 | AD57: =Messpunkte!E40
A58: =Messpunkte!E33 | D58: =Messpunkte!E34 | AK58: =Messpunkte!E41
...

Sheet Parameter
A1: Parameter und Annahmen
A3: Groesse | B3: Wert | C3: Herkunft
A4: Nullwert (Messwert in der Raummitte) | B4: 1464 | C4: mm - die eingekreiste Zahl in der Skizzenmitte. Aendern rechnet alles nach.
A5: Untere Raumkante | B5: 7600 | C5: mm - vom Nutzer vorgegeben, die einzige bekannte Laenge
A6: Raumtiefe rechter Schenkel | B6: 5004 | C6: mm - aus dem Foto ueber den Massstab der unteren Kante
A7: Knick: Breite linker Schenkel | B7: 4571 | C7: mm - geschaetzt aus dem Foto
A8: Knick: Tiefe linker Schenkel | B8: 3019 | C8: mm - geschaetzt aus dem Foto
A9: Massstab | B9: 5.4093 | C9: mm je Bildpunkt, aus 7600 mm / 1405 px
A10: Rastergroesse Plan | B10: 200 | C10: mm Kantenlaenge einer Zelle im Blatt Plan
A13: Vorzeichen
A14: Gemessen wurde mit Gliedermassstab auf dem Boden, abgelesen am Laser.
A15: Groesserer Messwert = Punkt liegt TIEFER. Hoehe = Nullwert - Messwert.
A16: Positive Hoehe = hoeher als die Raummitte, negative = tiefer.
A18: Positionen
A19: Alle x/y sind VISUELL aus dem Foto geschaetzt, nicht gemessen. Massstab ist
A20: allein die untere Raumkante mit 7600 mm. Rechne mit einigen Zentimetern
A21: Lageunsicherheit je Punkt; die Messwerte selbst sind davon unberuehrt.
A22: Nullpunkt der Koordinaten: Raumecke unten links, x nach rechts, y nach oben.
A24: Bereiche
A25: Nur 'Boden' ist die Flaeche dieses Raums. 'Kueche' und 'Nachbarraum' liegen
A26: hinter einer Stufe, 'Stufe' ist deren Oberkante, 'Schwelle' sind die in der
A27: Skizze eingekaestelten Punkte. Die Auswertung unten zaehlt nur 'Boden'.

Sheet Messpunkte
A1: Nr | B1: Bereich | C1: x [mm] | D1: y [mm] | E1: Messwert [mm] | F1: Hoehe rel. Mitte [mm] | G1: Bemerkung | H1: nur Raumboden [mm]
A2: 1 | B2: Kueche | C2: 4895 | D2: 4922 | E2: 1299 | F2: =Parameter!$B$4-E2 | G2: Tabelle oben rechts, Zeile Kueche | H2: =IF(B2="Boden",F2,"")
A3: 2 | B3: Kueche | C3: 6870 | D3: 4939 | E3: 1300 | F3: =Parameter!$B$4-E3 | G3: Tabelle oben rechts, Zeile Kueche | H3: =IF(B3="Boden",F3,"")
A4: 3 | B4: Stufe | C4: 4895 | D4: 4630 | E4: 1407 | F4: =Parameter!$B$4-E4 | G4: Tabelle oben rechts, Zeile Stufe | H4: =IF(B4="Boden",F4,"")
A5: 4 | B5: Stufe | C5: 6004 | D5: 4641 | E5: 1388 | F5: =Parameter!$B$4-E5 | G5: Tabelle oben rechts, Zeile Stufe | H5: =IF(B5="Boden",F5,"")
A6: 5 | B6: Stufe | C6: 7032 | D6: 4641 | E6: 1366 | F6: =Parameter!$B$4-E6 | G6: Tabelle oben rechts, Zeile Stufe | H6: =IF(B6="Boden",F6,"")
A7: 6 | B7: Boden | C7: 4868 | D7: 4327 | E7: 1444 | F7: =Parameter!$B$4-E7 | G7: Tabelle oben rechts, Zeile Boden | H7: =IF(B7="Boden",F7,"")
A8: 7 | B8: Boden | C8: 6004 | D8: 4327 | E8: 1458 | F8: =Parameter!$B$4-E8 | G8: Tabelle oben rechts, Zeile Boden | H8: =IF(B8="Boden",F8,"")
A9: 8 | B9: Boden | C9: 6951 | D9: 4327 | E9: 1458 | F9: =Parameter!$B$4-E9 | G9: Tabelle oben rechts, Zeile Boden | H9: =IF(B9="Boden",F9,"")
A10: 9 | B10: Boden | C10: 5317 | D10: 4035 | E10: 1455 | F10: =Parameter!$B$4-E10 | H10: =IF(B10="Boden",F10,"")
A11: 10 | B11: Boden | C11: 6843 | D11: 3814 | E11: 1463 | F11: =Parameter!$B$4-E11 | H11: =IF(B11="Boden",F11,"")
A12: 11 | B12: Boden | C12: 5788 | D12: 3462 | E12: 1463 | F12: =Parameter!$B$4-E12 | H12: =IF(B12="Boden",F12,"")
A13: 12 | B13: Nachbarraum | C13: 0 | D13: 3019 | E13: 1303 | F13: =Parameter!$B$4-E13 | G13: linkes Band, obere Zeile; Beschriftung lag ausserhalb, auf die Wand gesetzt | H13: =IF(B13="Boden",F13,"")
A14: 13 | B14: Nachbarraum | C14: 2083 | D14: 3019 | E14: 1304 | F14: =Parameter!$B$4-E14 | G14: linkes Band, obere Zeile; Beschriftung lag ausserhalb, auf die Wand gesetzt | H14: =IF(B14="Boden",F14,"")
A15: 14 | B15: Nachbarraum | C15: 4262 | D15: 3019 | E15: 1303 | F15: =Parameter!$B$4-E15 | G15: linkes Band, obere Zeile; Beschriftung lag ausserhalb, auf die Wand gesetzt | H15: =IF(B15="Boden",F15,"")
A16: 15 | B16: Stufe | C16: 27 | D16: 3019 | E16: 1434 | F16: =Parameter!$B$4-E16 | G16: eingekreist in der Skizze; Beschriftung lag ausserhalb, auf die Wand gesetzt | H16: =IF(B16="Boden",F16,"")
A17: 16 | B17: Stufe | C17: 325 | D17: 3019 | E17: 1373 | F17: =Parameter!$B$4-E17 | G17: linkes Band, mittlere Zeile; Beschriftung lag ausserhalb, auf die Wand gesetzt | H17: =IF(B17="Boden",F17,"")
A18: 17 | B18: Stufe | C18: 2110 | D18: 3019 | E18: 1394 | F18: =Parameter!$B$4-E18 | G18: linkes Band, mittlere Zeile; Beschriftung lag ausserhalb, auf die Wand gesetzt | H18: =IF(B18="Boden",F18,"")
A19: 18 | B19: Stufe | C19: 4284 | D19: 3019 | E19: 1398 | F19: =Parameter!$B$4-E19 | G19: linkes Band, mittlere Zeile; Beschriftung lag ausserhalb, auf die Wand gesetzt | H19: =IF(B19="Boden",F19,"")
A20: 19 | B20: Boden | C20: 460 | D20: 2813 | E20: 1470 | F20: =Parameter!$B$4-E20 | H20: =IF(B20="Boden",F20,"")
A21: 20 | B21: Boden | C21: 2110 | D21: 2856 | E21: 1472 | F21: =Parameter!$B$4-E21 | H21: =IF(B21="Boden",F21,"")
A22: 21 | B22: Boden | C22: 4300 | D22: 2872 | E22: 1465 | F22: =Parameter!$B$4-E22 | H22: =IF(B22="Boden",F22,"")
A23: 22 | B23: Boden | C23: 0 | D23: 2504 | E23: 1470 | F23: =Parameter!$B$4-E23 | G23: an der Tuer links; Beschriftung lag ausserhalb, auf die Wand gesetzt | H23: =IF(B23="Boden",F23,"")
A24: 23 | B24: Boden | C24: 3922 | D24: 2028 | E24: 1464 | F24: =Parameter!$B$4-E24 | G24: REFERENZ - eingekreist, die Null | H24: =IF(B24="Boden",F24,"")
A25: 24 | B25: Boden | C25: 1812 | D25: 1720 | E25: 1471 | F25: =Parameter!$B$4-E25 | H25: =IF(B25="Boden",F25,"")
A26: 25 | B26: Boden | C26: 6302 | D26: 1747 | E26: 1465 | F26: =Parameter!$B$4-E26 | H26: =IF(B26="Boden",F26,"")
A27: 26 | B27: Boden | C27: 7600 | D27: 2640 | E27: 1456 | F27: =Parameter!$B$4-E27 | G27: an der Wand rechts; Beschriftung lag ausserhalb, auf die Wand gesetzt | H27: =IF(B27="Boden",F27,"")
A28: 27 | B28: Boden | C28: 7600 | D28: 1341 | E28: 1452 | F28: =Parameter!$B$4-E28 | G28: an der Tuer rechts; Beschriftung lag ausserhalb, auf die Wand gesetzt | H28: =IF(B28="Boden",F28,"")
A29: 28 | B29: Boden | C29: 7600 | D29: 828 | E29: 1451 | F29: =Parameter!$B$4-E29 | G29: an der Wand rechts; Beschriftung lag ausserhalb, auf die Wand gesetzt | H29: =IF(B29="Boden",F29,"")
A30: 29 | B30: Boden | C30: 7600 | D30: 530 | E30: 1462 | F30: =Parameter!$B$4-E30 | G30: an der Wand rechts; Beschriftung lag ausserhalb, auf die Wand gesetzt | H30: =IF(B30="Boden",F30,"")
A31: 30 | B31: Boden | C31: 893 | D31: 746 | E31: 1467 | F31: =Parameter!$B$4-E31 | H31: =IF(B31="Boden",F31,"")
A32: 31 | B32: Boden | C32: 162 | D32: 530 | E32: 1466 | F32: =Parameter!$B$4-E32 | H32: =IF(B32="Boden",F32,"")
A33: 32 | B33: Schwelle | C33: 135 | D33: 195 | E33: 1429 | F33: =Parameter!$B$4-E33 | G33: im Kaestchen gezeichnet | H33: =IF(B33="Boden",F33,"")
A34: 33 | B34: Boden | C34: 622 | D34: 195 | E34: 1466 | F34: =Parameter!$B$4-E34 | H34: =IF(B34="Boden",F34,"")
A35: 34 | B35: Boden | C35: 3841 | D35: 828 | E35: 1464 | F35: =Parameter!$B$4-E35 | H35: =IF(B35="Boden",F35,"")
A36: 35 | B36: Boden | C36: 5896 | D36: 828 | E36: 1460 | F36: =Parameter!$B$4-E36 | H36: =IF(B36="Boden",F36,"")
A37: 36 | B37: Boden | C37: 3273 | D37: 368 | E37: 1453 | F37: =Parameter!$B$4-E37 | H37: =IF(B37="Boden",F37,"")
A38: 37 | B38: Schwelle | C38: 3786 | D38: 368 | E38: 1421 | F38: =Parameter!$B$4-E38 | G38: im Kaestchen gezeichnet | H38: =IF(B38="Boden",F38,"")
A39: 38 | B39: Boden | C39: 4219 | D39: 379 | E39: 1455 | F39: =Parameter!$B$4-E39 | H39: =IF(B39="Boden",F39,"")
A40: 39 | B40: Boden | C40: 5842 | D40: 395 | E40: 1455 | F40: =Parameter!$B$4-E40 | H40: =IF(B40="Boden",F40,"")
...
